Workbook
Name DSR: '1. Assumptions'!$B$6
Name AnnualInterestRate: '1. Assumptions'!$B$7
Name DownPaymentRate: '1. Assumptions'!$B$8
Name VariableIncomeWeight: '1. Assumptions'!$B$9
Name TransactionCostRate: '1. Assumptions'!$B$10
Name RentalYieldPct: '1. Assumptions'!$B$11
Name SafeBudgetMultiplier: '1. Assumptions'!$B$12
Name StretchBudgetMultiplier: '1. Assumptions'!$B$13
Name RiskZoneMultiplier: '1. Assumptions'!$B$14
Name RtoContractFeeRate: '1. Assumptions'!$B$15
Name RtoPriceMarkupRate: '1. Assumptions'!$B$16
Name RtoPaymentPerMillion: '1. Assumptions'!$B$17
Name RtoYear1Rate: '1. Assumptions'!$B$18
Name RtoYear2Rate: '1. Assumptions'!$B$19
Name RtoYear3Rate: '1. Assumptions'!$B$20
Name BuyLoanTenureYears: '1. Assumptions'!$B$21
Name RtoPeriodYears: '1. Assumptions'!$B$22
Name ComfortableThreshold: '1. Assumptions'!$B$23
Name TightThreshold: '1. Assumptions'!$B$24
Name ReadinessBudgetWeight: '1. Assumptions'!$B$25
Name ReadinessCashWeight: '1. Assumptions'!$B$26
Name ReadinessTimelineWeight: '1. Assumptions'!$B$27
Name PrimaryIncomeMonthly: '2. Inputs'!$B$6
Name AdditionalIncomeMonthly: '2. Inputs'!$B$7
Name BonusAnnual: '2. Inputs'!$B$8
Name HomeLoanMonthly: '2. Inputs'!$B$9
Name OtherDebtMonthly: '2. Inputs'!$B$10
Name MonthlyLivingExpenses: '2. Inputs'!$B$11
Name AnnualLumpSumExpenses: '2. Inputs'!$B$12
Name IsRenting: '2. Inputs'!$B$13
Name MonthlyRent: '2. Inputs'!$B$14
Name TotalSavings: '2. Inputs'!$B$15
Name AvailableDownPayment: '2. Inputs'!$B$16
Name MaxComfortableInstallment: '2. Inputs'!$B$17
Name TargetHomePrice: '2. Inputs'!$B$18
Name TargetTimelineMonths: '2. Inputs'!$B$19
Name ExpectedAppreciationPct: '2. Inputs'!$B$20
Name SteadyMonthlyIncome: '3. Income & Expenses'!$B$4
Name VariableMonthlyIncome: '3. Income & Expenses'!$B$5
Name GrossMonthlyIncome: '3. Income & Expenses'!$B$6
Name BankQualifyingMonthlyIncome: '3. Income & Expenses'!$B$7
Name TotalMonthlyDebt: '3. Income & Expenses'!$B$8
Name EffMonthlyRent: '3. Income & Expenses'!$B$10
Name MonthlyLumpSumEquivalent: '3. Income & Expenses'!$B$11
Name MonthlyCashFlowBeforeHousing: '3. Income & Expenses'!$B$12
Name MonthlySavingCapacity: '3. Income & Expenses'!$B$13
Name IncomeAfterOtherObligations: '3. Income & Expenses'!$B$15
Name AffordableByDSR: '4. Purchasing Power (Buy)'!$B$4
Name AffordableByBudget: '4. Purchasing Power (Buy)'!$B$5
Name RecommendedPreComfort: '4. Purchasing Power (Buy)'!$B$6
Name BindingPreComfort: '4. Purchasing Power (Buy)'!$B$7
Name RecommendedMonthlyInstallment: '4. Purchasing Power (Buy)'!$B$8
Name BindingInstallmentCeiling: '4. Purchasing Power (Buy)'!$B$9
Name BuyMonthlyRate: '4. Purchasing Power (Buy)'!$B$11
Name BuyNumPayments: '4. Purchasing Power (Buy)'!$B$12
Name BuyLoanFactor: '4. Purchasing Power (Buy)'!$B$13
Name LoanCapacity: '4. Purchasing Power (Buy)'!$B$14
Name MaxHomePrice: '4. Purchasing Power (Buy)'!$B$15
Name EstimatedLoanAmount: '4. Purchasing Power (Buy)'!$B$16
Name SafeBudget: '4. Purchasing Power (Buy)'!$B$18

Sheet 0. Read Me
A1: Home Ready — Calculation Logic Summary
A4: This workbook is a live, formula-driven mirror of every calculation in src/lib/calculations.ts (the Home Ready app's
A5: single source of truth for all numbers). Every yellow cell is an editable input or assumption; every white cell is a
A6: formula that recomputes automatically, exactly like the live app / its Master Mode.
A8: How to use it to check the app's logic:
A9: 1. Set Sheet 2 (Inputs) to match a real scenario — or open the app's Master Mode side-by-side and copy its values in.
A10: 2. Compare each computed number here to the same number shown in the app.
A11: 3. If anything disagrees, the sheet name + row label tells you exactly which TypeScript function to check
A12: (every formula's cell/row is labeled after its calculations.ts function name).
A14: Sheet map:
A15: 1. Assumptions — CalculationAssumptions (the tunable values Master Mode exposes, plus fixed constants).
A16: 2. Inputs — QuestionnaireAnswers (everything the questionnaire form collects).
... A105: • Home-Ready-Calculation-Audit.xlsx — an earlier audit pass.

Sheet 1. Assumptions
A1: Assumptions — CalculationAssumptions (src/types/finance.ts)
A3: Every value here feeds every sheet in this workbook by name. Change any cell to see the whole model recompute — exactly what Master Mode does in the live app.
A5: Assumption | B5: Value | C5: Named cell | D5: What it means
A6: Debt Service Ratio (DSR) | B6: 0.4 | C6: DSR | D6: Share of qualifying income a lender counts toward all debt, including the new mortgage.
A7: Annual Interest Rate | B7: 0.06 | C7: AnnualInterestRate | D7: Mortgage interest rate used to size the Buy loan.
A8: Down Payment Rate | B8: 0.1 | C8: DownPaymentRate | D8: Minimum down payment as a fraction of home price.
A9: Variable Income Weight | B9: 0.5 | C9: VariableIncomeWeight | D9: Portion of bonus a lender counts toward DSR-qualifying income.
A10: Transaction Cost Rate | B10: 0.02 | C10: TransactionCostRate | D10: Transfer + mortgage-registration fees, as a fraction of home price.
A11: Rental Yield % | B11: 0.04 | C11: RentalYieldPct | D11: Gross rental yield used to estimate market rent from a home price.
A12: Safe Budget Multiplier | B12: 0.85 | C12: SafeBudgetMultiplier | D12: Safe zone ceiling = this share of Recommended Home Price.
A13: Stretch Budget Multiplier | B13: 1 | C13: StretchBudgetMultiplier | D13: Stretch zone ceiling = this multiple of Recommended Home Price.
A14: Risk Zone Multiplier | B14: 1.06 | C14: RiskZoneMultiplier | D14: Above this multiple, a price is flagged meaningfully over budget.
A15: RTO Contract Fee Rate | B15: 0.07 | C15: RtoContractFeeRate | D15: One-time RTO contract fee, as a fraction of home price.
A16: RTO Price Markup Rate | B16: 0.06 | C16: RtoPriceMarkupRate | D16: Markup the RTO contract price carries over the plain home price.
A17: RTO Payment per ฿1,000,000 | B17: 6800 | C17: RtoPaymentPerMillion | D17: Flat monthly RTO payment per ฿1,000,000 of RTO contract price.
... A26: Readiness Weight — Down Payment Coverage | B26: 0.35 | C26: ReadinessCashWeight | D26: Weight of downPaymentCoverage in the Readiness Score composite (READINESS_DOWN_PAYMENT_WEIGHT in code — named cell kept as ReadinessCashWeight, same value).
A27: Readiness Weight — Timeline Fit | B27: 0.15 | C27: ReadinessTimelineWeight

Sheet 2. Inputs
A1: Inputs — QuestionnaireAnswers (src/lib/defaults.ts DEFAULT_ANSWERS)
A3: Pre-filled with the app's own DEFAULT_ANSWERS. Edit these to match any real scenario you want to check against the live app / Master Mode.
A5: Input | B5: Value | C5: Named cell | D5: Note
A6: Primary income (monthly) | B6: 35000 | C6: PrimaryIncomeMonthly
A7: Additional income (monthly) | B7: 0 | C7: AdditionalIncomeMonthly
A8: Annual bonus | B8: 0 | C8: BonusAnnual
A9: Existing home loan payment (monthly) | B9: 0 | C9: HomeLoanMonthly
A10: Other loan payments (monthly) | B10: 3000 | C10: OtherDebtMonthly
A11: Monthly living expenses | B11: 12000 | C11: MonthlyLivingExpenses
A12: Annual lump-sum expenses | B12: 20000 | C12: AnnualLumpSumExpenses
A13: Currently renting? (1 = yes, 0 = no) | B13: 1 | C13: IsRenting
A14: Monthly rent | B14: 8000 | C14: MonthlyRent
A15: Total current savings | B15: 150000 | C15: TotalSavings
A16: Available for a down payment | B16: 100000 | C16: AvailableDownPayment
A17: Max comfortable installment (0 = no cap) | B17: 0 | C17: MaxComfortableInstallment | D17: Not a form field — the form always writes 0 here (DEFAULT_ANSWERS), which calculateInstallmentCeilings' >0 guard treats as 'no comfort cap.' Edit this cell only to hypothetically test what a comfort cap would do.
A18: Your Target Home Price | B18: 3000000 | C18: TargetHomePrice
A19: Timeline to buy (months) | B19: 24 | C19: TargetTimelineMonths
A20: Expected annual capital growth | B20: 0.04 | C20: ExpectedAppreciationPct | D20: Not a form field, and not exposed in Master Mode either — held at a fixed system default (4%). Edit this cell only to hypothetically test a different capital-growth assumption.
A21: Co-borrower income (monthly) | B21: 0 | C21: CoBorrowerIncomeMonthly | D21: Optional. Counted at full weight in Steady Monthly Income — same treatment as Primary/Additional income, never discounted by Variable Income Weight (that discount is for bonus only).
A22: Co-borrower debt (monthly) | B22: 0 | C22: CoBorrowerDebtMonthly | D22: Optional. Added to Total Monthly Debt alongside co-borrower income — without this, counting a co-borrower's income but not their debt would overstate affordability.
A24: "Your Target Home Price" is DEFAULT_ANSWERS' own starting value (฿3,000,000) — change it freely to test the Gap & Plan / Target-basis sheets at any price.

Sheet 3. Income & Expenses
A1: Income & Expenses — calculateIncomeProfile / resolveExpenseProfile
A4: Steady Monthly Income | B4: =PrimaryIncomeMonthly+AdditionalIncomeMonthly+CoBorrowerIncomeMonthly | C4: Primary + additional + co-borrower — excludes bonus, even averaged. Co-borrower income is included at the same full weight as the applicant's own (see Sheet 2 note).
A5: Variable Monthly Income | B5: =BonusAnnual/12
A6: Gross Monthly Income | B6: =SteadyMonthlyIncome+VariableMonthlyIncome | C6: Used for DSR/Budget affordability ceilings — NOT for Remaining Monthly Income (see Sheet 8).
A7: Bank-Qualifying Monthly Income | B7: =SteadyMonthlyIncome+VariableMonthlyIncome*VariableIncomeWeight | C7: Bonus counted at a discount — banks don't treat it as guaranteed.
A8: Total Monthly Debt | B8: =HomeLoanMonthly+OtherDebtMonthly+CoBorrowerDebtMonthly | C8: Applicant's own debt + co-borrower's own debt, kept symmetric with row 4.
A10: Effective Monthly Rent (0 if not renting) | B10: =IF(IsRenting=1,MonthlyRent,0)
A11: Monthly Lump-Sum Equivalent | B11: =AnnualLumpSumExpenses/12
A12: Monthly Cash Flow Before Housing | B12: =GrossMonthlyIncome-TotalMonthlyDebt-MonthlyLivingExpenses-MonthlyLumpSumEquivalent-EffMonthlyRent | C12: Can go negative — that's the Advisory Notice trigger (Sheet 14), never clamped here.
A13: Monthly Saving Capacity | B13: =MAX(0,MonthlyCashFlowBeforeHousing)
A15: Income After Other Obligations | B15: =SteadyMonthlyIncome-TotalMonthlyDebt-MonthlyLivingExpenses-MonthlyLumpSumEquivalent | C15: steadyMonthlyIncome minus debt/living/lump-sum — the baseline every scenario's Remaining Monthly Income (Sheet 8) subtracts its own housing payment from.

Sheet 4. Purchasing Power (Buy)
A1: Purchasing Power — calculatePurchasingPower / calculateInstallmentCeilings
A4: Affordable by DSR | B4: =MAX(0,BankQualifyingMonthlyIncome*DSR-TotalMonthlyDebt)
A5: Affordable by Budget | B5: =MAX(0,GrossMonthlyIncome-TotalMonthlyDebt-MonthlyLivingExpenses-MonthlyLumpSumEquivalent) | C5: Rent excluded — it's replaced by the mortgage payment once bought, not stacked on top.
A6: Recommended Installment (before comfort cap) | B6: =MIN(AffordableByDSR,AffordableByBudget)
A7: Binding Ceiling (before comfort cap) | B7: =IF(AffordableByDSR<=AffordableByBudget,"dsr","budget")
A8: Recommended Monthly Installment | B8: =IF(AND(MaxComfortableInstallment>0,MaxComfortableInstallment<RecommendedPreComfort),MaxComfortableInstallment,RecommendedPreComfort)
A9: Binding Installment Ceiling | B9: =IF(AND(MaxComfortableInstallment>0,MaxComfortableInstallment<RecommendedPreComfort),"comfort",BindingPreComfort)
A11: Monthly Rate (Buy) | B11: =AnnualInterestRate/12
A12: # Payments (Buy, 30yr) | B12: =BuyLoanTenureYears*12
A13: Loan Factor (Buy) | B13: =IF(BuyNumPayments<=0,0,IF(BuyMonthlyRate=0,BuyNumPayments,(1-(1+BuyMonthlyRate)^-BuyNumPayments)/BuyMonthlyRate)) | C13: loanFactor(): standard annuity present-value factor.
A14: Loan Capacity | B14: =RecommendedMonthlyInstallment*BuyLoanFactor
A15: Recommended Home Price (Max Home Price) | B15: =IF(DownPaymentRate<1,LoanCapacity/(1-DownPaymentRate),0) | C15: The home price supported by borrowing/repayment capacity alone, assuming the minimum required down payment. Deliberately does NOT include AvailableDownPayment — today's cash doesn't raise or lower this ceiling; see Sheet 4a/4b for the separate cash-readiness question. (Was LoanCapacity+AvailableDownPayment — changed so extra cash can't silently raise this affordability ceiling.)
A16: Estimated Loan Amount | B16: =MAX(0,MaxHomePrice-AvailableDownPayment) | C16: Loan needed at Max Home Price using REAL AvailableDownPayment (not the assumed minimum Max Home Price itself assumes) — can now exceed Loan Capacity when available cash is thinner than the minimum this price implies (MaxHomePrice*DownPaymentRate). Not a bug — the same shortfall the Down Payment Gap (Sheet 4a/4b) surfaces separately. Not shown in the app UI.
A18: Safe Budget (zone bar, green) | B18: =MaxHomePrice*SafeBudgetMultiplier
A19: Stretch Budget (zone bar, amber) | B19: =MaxHomePrice*StretchBudgetMultiplier
A20: Risk Zone Threshold (zone bar, red) | B20: =MaxHomePrice*RiskZoneMultiplier
A21: Buy's displayed “Home price gap” / “Close the home price gap” / Additional Option logic now lives in Sheet 4a/4b (“Home Price Gap & Plan”) — shared verbatim with RTO via calculateBuyGapNarrative. See those sheets.

Sheet 4a. Home Price Gap (Rec)
A1: Home Price Gap & Plan (shared: Buy + RTO) — calculateBuyGapNarrative, basis = Recommended Home Price
A3: Buy and RTO share ONE financial-eligibility ceiling — this sheet is the literal source for Buy's ‘Home price gap’ / ‘Close the home price gap’ rows AND RTO's identical rows in the app (BuyContent and RtoContent in GapAndPlan.tsx both call this exact function with this exact basis). In the app a GAP row is hidden whenever its amount is ฿0.
A5: THE GAP
A6: Home Price Basis | B6: =MaxHomePrice
A7: Price Gap | B7: =MAX(0,HpgBasis_Rec-MaxHomePrice)
A8: Is Price Gap Closed | B8: =HpgPriceGap_Rec=0
A9: Required Down Payment (at this basis) | B9: =HpgBasis_Rec*DownPaymentRate
A10: Remaining Down Payment | B10: =MAX(0,HpgRequiredDownPayment_Rec-AvailableDownPayment) | C10: This is Buy's ‘Down payment gap’ GAP row.
A11: Transaction Cost Estimate | B11: =HpgBasis_Rec*TransactionCostRate | C11: Buy's ‘Transaction fees’ GAP row — always shown, never hidden at ฿0 (a cost to prepare for, not a shortfall).
A13: THE PLAN
A14: Additional Monthly Installment Needed | B14: =IF(BuyLoanFactor>0,HpgPriceGap_Rec*(1-DownPaymentRate)/BuyLoanFactor,0) | C14: Accounts for Max Home Price's LoanCapacity/(1-DownPaymentRate) construction: each ฿1 of extra loan capacity raises Max Home Price by 1/(1-DownPaymentRate), so closing Price Gap needs only PriceGap*(1-DownPaymentRate) of extra capacity, not PriceGap itself. This is now the ONLY lever — extra down payment cash no longer closes Price Gap at all (Max Home Price doesn't respond to it).
A15: Required Monthly Installment for Target | B15: =RecommendedMonthlyInstallment+HpgAdditionalInstallment_Rec | C15: ‘Close the home price gap’ PLAN row action text uses these two cells.
A17: ADDITIONAL OPTION (identical wording for Buy and RTO)
A18: Downsize Suggestion | B18: =IF(HpgBasis_Rec>RiskZoneThreshold,"over-risk-budget",IF(HpgBasis_Rec>StretchBudget,"stretch-zone","none"))
A19: Amount over Stretch Budget (if over-risk-budget) | B19: =MAX(0,HpgBasis_Rec-StretchBudget)

Sheet 4b. Home Price Gap (Tgt)
A1: Home Price Gap & Plan (shared: Buy + RTO) — calculateBuyGapNarrative, basis = Target Home Price
A3: Buy and RTO share ONE financial-eligibility ceiling — this sheet is the literal source for Buy's ‘Home price gap’ / ‘Close the home price gap’ rows AND RTO's identical rows in the app (BuyContent and RtoContent in GapAndPlan.tsx both call this exact function with this exact basis). In the app a GAP row is hidden whenever its amount is ฿0.
A5: THE GAP
A6: Home Price Basis | B6: =TargetHomePrice
A7: Price Gap | B7: =MAX(0,HpgBasis_Tgt-MaxHomePrice)
A8: Is Price Gap Closed | B8: =HpgPriceGap_Tgt=0
A9: Required Down Payment (at this basis) | B9: =HpgBasis_Tgt*DownPaymentRate
A10: Remaining Down Payment | B10: =MAX(0,HpgRequiredDownPayment_Tgt-AvailableDownPayment) | C10: This is Buy's ‘Down payment gap’ GAP row.
A11: Transaction Cost Estimate | B11: =HpgBasis_Tgt*TransactionCostRate | C11: Buy's ‘Transaction fees’ GAP row — always shown, never hidden at ฿0 (a cost to prepare for, not a shortfall).
A13: THE PLAN
A14: Additional Monthly Installment Needed | B14: =IF(BuyLoanFactor>0,HpgPriceGap_Tgt*(1-DownPaymentRate)/BuyLoanFactor,0) | C14: Accounts for Max Home Price's LoanCapacity/(1-DownPaymentRate) construction: each ฿1 of extra loan capacity raises Max Home Price by 1/(1-DownPaymentRate), so closing Price Gap needs only PriceGap*(1-DownPaymentRate) of extra capacity, not PriceGap itself. This is now the ONLY lever — extra down payment cash no longer closes Price Gap at all (Max Home Price doesn't respond to it).
A15: Required Monthly Installment for Target | B15: =RecommendedMonthlyInstallment+HpgAdditionalInstallment_Tgt | C15: ‘Close the home price gap’ PLAN row action text uses these two cells.
A17: ADDITIONAL OPTION (identical wording for Buy and RTO)
A18: Downsize Suggestion | B18: =IF(HpgBasis_Tgt>RiskZoneThreshold,"over-risk-budget",IF(HpgBasis_Tgt>StretchBudget,"stretch-zone","none"))
A19: Amount over Stretch Budget (if over-risk-budget) | B19: =MAX(0,HpgBasis_Tgt-StretchBudget)

Sheet 5. Action Plan (Buy)
A1: Action Plan — calculateActionPlan (down-payment-only savings timeline, at Target Home Price)
A4: Required Down Payment | B4: =TargetHomePrice*DownPaymentRate | C4: Down payment only — NOT full cash-at-closing.
A5: Remaining Down Payment | B5: =MAX(0,RequiredDownPayment-AvailableDownPayment)
A6: Is Down Payment Ready | B6: =RemainingDownPayment=0
A7: Transaction Cost Estimate | B7: =TargetHomePrice*TransactionCostRate | C7: Shown separately in The Gap & The Plan — never subtracted from Required/Remaining Down Payment above, never feeds Readiness.
A9: Months to Ready | B9: =IF(IsDownPaymentReady,0,IF(MonthlySavingCapacity>0,CEILING(RemainingDownPayment/MonthlySavingCapacity,1),"N/A (saving $0/mo)"))
A10: Years to Ready | B10: =IF(ISNUMBER(MonthsToReady),ROUND(MonthsToReady/12,1),"N/A")
A11: Is On Target Timeline | B11: =IF(ISNUMBER(MonthsToReady),MonthsToReady<=TargetTimelineMonths,"N/A")
A12: Shortfall Months (if behind schedule) | B12: =IF(AND(ISNUMBER(MonthsToReady),MonthsToReady>TargetTimelineMonths),MonthsToReady-TargetTimelineMonths,"-")
A13: Required Monthly Saving for Target Timeline | B13: =CEILING(RemainingDownPayment/TargetTimelineMonths,1)
A14: Suggested Monthly Savings Increase | B14: =MAX(0,RequiredMonthlySavingForTarget-MonthlySavingCapacity)

Sheet 6. Readiness Score
A1: Readiness Score — calculateReadiness
A4: Down Payment Coverage % | B4: =IF(RequiredDownPayment>0,MIN(100,MAX(0,AvailableDownPayment/RequiredDownPayment*100)),100) | C4: calculateReadiness(): down-payment-only — Transaction Cost Estimate never dilutes this score.
A5: Budget Fit % | B5: =IF(TargetHomePrice>0,MIN(100,MAX(0,MaxHomePrice/TargetHomePrice*100)),100)
A6: Timeline Fit % | B6: =IF(MonthsToReady=0,100,IF(OR(NOT(ISNUMBER(MonthsToReady)),TargetTimelineMonths<=0),0,MIN(100,MAX(0,TargetTimelineMonths/MonthsToReady*100))))
A8: Readiness % (weighted composite) | B8: =ROUND(ReadinessBudgetWeight*BudgetFit+ReadinessCashWeight*DownPaymentCoverage+ReadinessTimelineWeight*TimelineFit,0) | C8: Weights: Budget Fit 50%, Down Payment Coverage 35%, Timeline Fit 15%.
A9: Status | B9: =IF(ReadinessPercent>=85,"Ready",IF(ReadinessPercent>=65,"Almost Ready",IF(ReadinessPercent>=45,"Almost Ready",IF(ReadinessPercent>=25,"Not Ready","Not Ready"))))
A10: Archetype | B10: =IF(ReadinessPercent>=85,"buy-now",IF(ReadinessPercent>=65,"near-ready",IF(ReadinessPercent>=45,"emerging-buyer",IF(ReadinessPercent>=25,"early-preparation","rent-for-now")))) | C10: Still computed — no longer displayed on the results page (UI-only change, ReadinessScore.tsx).
A12: Thresholds: ≥85 Ready/buy-now • ≥65 Almost Ready/near-ready • ≥45 Almost Ready/emerging-buyer • ≥25 Not Ready/early-preparation • else Not Ready/rent-for-now.

Sheet 7a. Wealth — Recommended
A1: 10-Year Wealth Comparison (Buy) — calculateWealthComparison, basis = MaxHomePrice
A4: Home Price Basis | B4: =MaxHomePrice
A5: Loan for Home | B5: =MAX(0,MaxHomePrice-MaxHomePrice*DownPaymentRate) | C5: Uses the ASSUMED minimum down payment (MaxHomePrice*DownPaymentRate), NOT AvailableDownPayment — same standard financing assumption Sheet 7b (Target Price) now also uses: the modeled mortgage is always sized off the minimum required down payment, never real cash. Real AvailableDownPayment is used only for the separate Down Payment Gap (Sheet 4a/4b), never for sizing the modeled loan.
A6: Installment for Home (30yr) | B6: =IF(BuyLoanFactor>0,LoanForHome_MaxHomePrice/BuyLoanFactor,0) | C6: This is the scenario's "Monthly payment" figure for Buy in the comparison grid.
A7: Estimated Monthly Rent (for this basis) | B7: =MaxHomePrice*RentalYieldPct/12 | C7: Rent scenario's "Monthly payment" figure — market rent estimated from the SAME home price.
A9: Year | B9: Home Value | C9: Loan Balance | D9: Home Equity | E9: Total Mortgage Paid | F9: Total Rent Paid
A10: 1 | B10: =MaxHomePrice*(1+ExpectedAppreciationPct)^1 | C10: =IF(LoanForHome_MaxHomePrice<=0,0,IF(BuyMonthlyRate=0,MAX(0,LoanForHome_MaxHomePrice-Installment_MaxHomePrice*12),MAX(0,LoanForHome_MaxHomePrice*(1+BuyMonthlyRate)^(12)-Installment_MaxHomePrice*(((1+BuyMonthlyRate)^(12)-1)/BuyMonthlyRate)))) | D10: =B10-C10 | E10: =Installment_MaxHomePrice*MIN(1*12,BuyLoanTenureYears*12) | F10: =EstMonthlyRent_MaxHomePrice*12
A11: 2 | B11: =MaxHomePrice*(1+ExpectedAppreciationPct)^2 | C11: =IF(LoanForHome_MaxHomePrice<=0,0,IF(BuyMonthlyRate=0,MAX(0,LoanForHome_MaxHomePrice-Installment_MaxHomePrice*24),MAX(0,LoanForHome_MaxHomePrice*(1+BuyMonthlyRate)^(24)-Installment_MaxHomePrice*(((1+BuyMonthlyRate)^(24)-1)/BuyMonthlyRate)))) | D11: =B11-C11 | E11: =Installment_MaxHomePrice*MIN(2*12,BuyLoanTenureYears*12) | F11: =F10+MaxHomePrice*(1+ExpectedAppreciationPct)^1*RentalYieldPct
A12: 3 | B12: =MaxHomePrice*(1+ExpectedAppreciationPct)^3 | C12: =IF(LoanForHome_MaxHomePrice<=0,0,IF(BuyMonthlyRate=0,MAX(0,LoanForHome_MaxHomePrice-Installment_MaxHomePrice*36),MAX(0,LoanForHome_MaxHomePrice*(1+BuyMonthlyRate)^(36)-Installment_MaxHomePrice*(((1+BuyMonthlyRate)^(36)-1)/BuyMonthlyRate)))) | D12: =B12-C12 | E12: =Installment_MaxHomePrice*MIN(3*12,BuyLoanTenureYears*12) | F12: =F11+MaxHomePrice*(1+ExpectedAppreciationPct)^2*RentalYieldPct
A13: 4 | B13: =MaxHomePrice*(1+ExpectedAppreciationPct)^4 | C13: =IF(LoanForHome_MaxHomePrice<=0,0,IF(BuyMonthlyRate=0,MAX(0,LoanForHome_MaxHomePrice-Installment_MaxHomePrice*48),MAX(0,LoanForHome_MaxHomePrice*(1+BuyMonthlyRate)^(48)-Installment_MaxHomePrice*(((1+BuyMonthlyRate)^(48)-1)/BuyMonthlyRate)))) | D13: =B13-C13 | E13: =Installment_MaxHomePrice*MIN(4*12,BuyLoanTenureYears*12) | F13: =F12+MaxHomePrice*(1+ExpectedAppreciationPct)^3*RentalYieldPct
A14: 5 | B14: =MaxHomePrice*(1+ExpectedAppreciationPct)^5 | C14: =IF(LoanForHome_MaxHomePrice<=0,0,IF(BuyMonthlyRate=0,MAX(0,LoanForHome_MaxHomePrice-Installment_MaxHomePrice*60),MAX(0,LoanForHome_MaxHomePrice*(1+BuyMonthlyRate)^(60)-Installment_MaxHomePrice*(((1+BuyMonthlyRate)^(60)-1)/BuyMonthlyRate)))) | D14: =B14-C14 | E14: =Installment_MaxHomePrice*MIN(5*12,BuyLoanTenureYears*12) | F14: =F13+MaxHomePrice*(1+ExpectedAppreciationPct)^4*RentalYieldPct
A15: 6 | B15: =MaxHomePrice*(1+ExpectedAppreciationPct)^6 | C15: =IF(LoanForHome_MaxHomePrice<=0,0,IF(BuyMonthlyRate=0,MAX(0,LoanForHome_MaxHomePrice-Installment_MaxHomePrice*72),MAX(0,LoanForHome_MaxHomePrice*(1+BuyMonthlyRate)^(72)-Installment_MaxHomePrice*(((1+BuyMonthlyRate)^(72)-1)/BuyMonthlyRate)))) | D15: =B15-C15 | E15: =Installment_MaxHomePrice*MIN(6*12,BuyLoanTenureYears*12) | F15: =F14+MaxHomePrice*(1+ExpectedAppreciationPct)^5*RentalYieldPct
A16: 7 | B16: =MaxHomePrice*(1+ExpectedAppreciationPct)^7 | C16: =IF(LoanForHome_MaxHomePrice<=0,0,IF(BuyMonthlyRate=0,MAX(0,LoanForHome_MaxHomePrice-Installment_MaxHomePrice*84),MAX(0,LoanForHome_MaxHomePrice*(1+BuyMonthlyRate)^(84)-Installment_MaxHomePrice*(((1+BuyMonthlyRate)^(84)-1)/BuyMonthlyRate)))) | D16: =B16-C16 | E16: =Installment_MaxHomePrice*MIN(7*12,BuyLoanTenureYears*12) | F16: =F15+MaxHomePrice*(1+ExpectedAppreciationPct)^6*RentalYieldPct
A17: 8 | B17: =MaxHomePrice*(1+ExpectedAppreciationPct)^8 | C17: =IF(LoanForHome_MaxHomePrice<=0,0,IF(BuyMonthlyRate=0,MAX(0,LoanForHome_MaxHomePrice-Installment_MaxHomePrice*96),MAX(0,LoanForHome_MaxHomePrice*(1+BuyMonthlyRate)^(96)-Installment_MaxHomePrice*(((1+BuyMonthlyRate)^(96)-1)/BuyMonthlyRate)))) | D17: =B17-C17 | E17: =Installment_MaxHomePrice*MIN(8*12,BuyLoanTenureYears*12) | F17: =F16+MaxHomePrice*(1+ExpectedAppreciationPct)^7*RentalYieldPct
A18: 9 | B18: =MaxHomePrice*(1+ExpectedAppreciationPct)^9 | C18: =IF(LoanForHome_MaxHomePrice<=0,0,IF(BuyMonthlyRate=0,MAX(0,LoanForHome_MaxHomePrice-Installment_MaxHomePrice*108),MAX(0,LoanForHome_MaxHomePrice*(1+BuyMonthlyRate)^(108)-Installment_MaxHomePrice*(((1+BuyMonthlyRate)^(108)-1)/BuyMonthlyRate)))) | D18: =B18-C18 | E18: =Installment_MaxHomePrice*MIN(9*12,BuyLoanTenureYears*12) | F18: =F17+MaxHomePrice*(1+ExpectedAppreciationPct)^8*RentalYieldPct
A19: 10 | B19: =MaxHomePrice*(1+ExpectedAppreciationPct)^10 | C19: =IF(LoanForHome_MaxHomePrice<=0,0,IF(BuyMonthlyRate=0,MAX(0,LoanForHome_MaxHomePrice-Installment_MaxHomePrice*120),MAX(0,LoanForHome_MaxHomePrice*(1+BuyMonthlyRate)^(120)-Installment_MaxHomePrice*(((1+BuyMonthlyRate)^(120)-1)/BuyMonthlyRate)))) | D19: =B19-C19 | E19: =Installment_MaxHomePrice*MIN(10*12,BuyLoanTenureYears*12) | F19: =F18+MaxHomePrice*(1+ExpectedAppreciationPct)^9*RentalYieldPct
A21: Loan Balance (col C): exponent is parenthesized — ^(months), not ^months — since Excel's ^ binds tighter than *; ^N*12 would silently compute (base)^N*12 instead of (base)^(N*12), understating growth so badly the balance clamped to ฿0 every year.
A22: Total Rent Paid (col F): cumulative, not EstMonthlyRent*months — rent grows with the property's own appreciation at the same constant RentalYieldPct (year 1 = 12*EstMonthlyRent exactly; each later year adds that year's own higher annual rent).
A23: Affordable Home Value @ Year 10 (= Capital Value, Buy) | B23: =B19 | C23: Also used verbatim as RTO's own Year-10 Capital Value at this same basis (Sheet 8/9) — a home's market value doesn't depend on how it was financed.

Sheet 7b. Wealth — Target Price
A1: 10-Year Wealth Comparison (Buy) — calculateWealthComparison, basis = TargetHomePrice
A4: Home Price Basis | B4: =TargetHomePrice
A5: Loan for Home | B5: =MAX(0,TargetHomePrice-TargetHomePrice*DownPaymentRate) | C5: Uses the ASSUMED minimum down payment (TargetHomePrice*DownPaymentRate), NOT AvailableDownPayment — same standard financing assumption as Recommended (Sheet 7a): the modeled mortgage is always sized off the minimum required down payment, never real cash. Real AvailableDownPayment is used only for the separate Down Payment Gap (Sheet 4a/4b), never for sizing the modeled loan. (Was TargetHomePrice-AvailableDownPayment — that made Target's modeled installment diverge from a household's real cash position, which the Down Payment Gap already covers on its own.)
A6: Installment for Home (30yr) | B6: =IF(BuyLoanFactor>0,LoanForHome_TargetHomePrice/BuyLoanFactor,0) | C6: This is the scenario's "Monthly payment" figure for Buy in the comparison grid.
A7: Estimated Monthly Rent (for this basis) | B7: =TargetHomePrice*RentalYieldPct/12 | C7: Rent scenario's "Monthly payment" figure — market rent estimated from the SAME home price.
A9: Year | B9: Home Value | C9: Loan Balance | D9: Home Equity | E9: Total Mortgage Paid | F9: Total Rent Paid
A10: 1 | B10: =TargetHomePrice*(1+ExpectedAppreciationPct)^1 | C10: =IF(LoanForHome_TargetHomePrice<=0,0,IF(BuyMonthlyRate=0,MAX(0,LoanForHome_TargetHomePrice-Installment_TargetHomePrice*12),MAX(0,LoanForHome_TargetHomePrice*(1+BuyMonthlyRate)^(12)-Installment_TargetHomePrice*(((1+BuyMonthlyRate)^(12)-1)/BuyMonthlyRate)))) | D10: =B10-C10 | E10: =Installment_TargetHomePrice*MIN(1*12,BuyLoanTenureYears*12) | F10: =EstMonthlyRent_TargetHomePrice*12
A11: 2 | B11: =TargetHomePrice*(1+ExpectedAppreciationPct)^2 | C11: =IF(LoanForHome_TargetHomePrice<=0,0,IF(BuyMonthlyRate=0,MAX(0,LoanForHome_TargetHomePrice-Installment_TargetHomePrice*24),MAX(0,LoanForHome_TargetHomePrice*(1+BuyMonthlyRate)^(24)-Installment_TargetHomePrice*(((1+BuyMonthlyRate)^(24)-1)/BuyMonthlyRate)))) | D11: =B11-C11 | E11: =Installment_TargetHomePrice*MIN(2*12,BuyLoanTenureYears*12) | F11: =F10+TargetHomePrice*(1+ExpectedAppreciationPct)^1*RentalYieldPct
A12: 3 | B12: =TargetHomePrice*(1+ExpectedAppreciationPct)^3 | C12: =IF(LoanForHome_TargetHomePrice<=0,0,IF(BuyMonthlyRate=0,MAX(0,LoanForHome_TargetHomePrice-Installment_TargetHomePrice*36),MAX(0,LoanForHome_TargetHomePrice*(1+BuyMonthlyRate)^(36)-Installment_TargetHomePrice*(((1+BuyMonthlyRate)^(36)-1)/BuyMonthlyRate)))) | D12: =B12-C12 | E12: =Installment_TargetHomePrice*MIN(3*12,BuyLoanTenureYears*12) | F12: =F11+TargetHomePrice*(1+ExpectedAppreciationPct)^2*RentalYieldPct
A13: 4 | B13: =TargetHomePrice*(1+ExpectedAppreciationPct)^4 | C13: =IF(LoanForHome_TargetHomePrice<=0,0,IF(BuyMonthlyRate=0,MAX(0,LoanForHome_TargetHomePrice-Installment_TargetHomePrice*48),MAX(0,LoanForHome_TargetHomePrice*(1+BuyMonthlyRate)^(48)-Installment_TargetHomePrice*(((1+BuyMonthlyRate)^(48)-1)/BuyMonthlyRate)))) | D13: =B13-C13 | E13: =Installment_TargetHomePrice*MIN(4*12,BuyLoanTenureYears*12) | F13: =F12+TargetHomePrice*(1+ExpectedAppreciationPct)^3*RentalYieldPct
A14: 5 | B14: =TargetHomePrice*(1+ExpectedAppreciationPct)^5 | C14: =IF(LoanForHome_TargetHomePrice<=0,0,IF(BuyMonthlyRate=0,MAX(0,LoanForHome_TargetHomePrice-Installment_TargetHomePrice*60),MAX(0,LoanForHome_TargetHomePrice*(1+BuyMonthlyRate)^(60)-Installment_TargetHomePrice*(((1+BuyMonthlyRate)^(60)-1)/BuyMonthlyRate)))) | D14: =B14-C14 | E14: =Installment_TargetHomePrice*MIN(5*12,BuyLoanTenureYears*12) | F14: =F13+TargetHomePrice*(1+ExpectedAppreciationPct)^4*RentalYieldPct
A15: 6 | B15: =TargetHomePrice*(1+ExpectedAppreciationPct)^6 | C15: =IF(LoanForHome_TargetHomePrice<=0,0,IF(BuyMonthlyRate=0,MAX(0,LoanForHome_TargetHomePrice-Installment_TargetHomePrice*72),MAX(0,LoanForHome_TargetHomePrice*(1+BuyMonthlyRate)^(72)-Installment_TargetHomePrice*(((1+BuyMonthlyRate)^(72)-1)/BuyMonthlyRate)))) | D15: =B15-C15 | E15: =Installment_TargetHomePrice*MIN(6*12,BuyLoanTenureYears*12) | F15: =F14+TargetHomePrice*(1+ExpectedAppreciationPct)^5*RentalYieldPct
A16: 7 | B16: =TargetHomePrice*(1+ExpectedAppreciationPct)^7 | C16: =IF(LoanForHome_TargetHomePrice<=0,0,IF(BuyMonthlyRate=0,MAX(0,LoanForHome_TargetHomePrice-Installment_TargetHomePrice*84),MAX(0,LoanForHome_TargetHomePrice*(1+BuyMonthlyRate)^(84)-Installment_TargetHomePrice*(((1+BuyMonthlyRate)^(84)-1)/BuyMonthlyRate)))) | D16: =B16-C16 | E16: =Installment_TargetHomePrice*MIN(7*12,BuyLoanTenureYears*12) | F16: =F15+TargetHomePrice*(1+ExpectedAppreciationPct)^6*RentalYieldPct
A17: 8 | B17: =TargetHomePrice*(1+ExpectedAppreciationPct)^8 | C17: =IF(LoanForHome_TargetHomePrice<=0,0,IF(BuyMonthlyRate=0,MAX(0,LoanForHome_TargetHomePrice-Installment_TargetHomePrice*96),MAX(0,LoanForHome_TargetHomePrice*(1+BuyMonthlyRate)^(96)-Installment_TargetHomePrice*(((1+BuyMonthlyRate)^(96)-1)/BuyMonthlyRate)))) | D17: =B17-C17 | E17: =Installment_TargetHomePrice*MIN(8*12,BuyLoanTenureYears*12) | F17: =F16+TargetHomePrice*(1+ExpectedAppreciationPct)^7*RentalYieldPct
A18: 9 | B18: =TargetHomePrice*(1+ExpectedAppreciationPct)^9 | C18: =IF(LoanForHome_TargetHomePrice<=0,0,IF(BuyMonthlyRate=0,MAX(0,LoanForHome_TargetHomePrice-Installment_TargetHomePrice*108),MAX(0,LoanForHome_TargetHomePrice*(1+BuyMonthlyRate)^(108)-Installment_TargetHomePrice*(((1+BuyMonthlyRate)^(108)-1)/BuyMonthlyRate)))) | D18: =B18-C18 | E18: =Installment_TargetHomePrice*MIN(9*12,BuyLoanTenureYears*12) | F18: =F17+TargetHomePrice*(1+ExpectedAppreciationPct)^8*RentalYieldPct
A19: 10 | B19: =TargetHomePrice*(1+ExpectedAppreciationPct)^10 | C19: =IF(LoanForHome_TargetHomePrice<=0,0,IF(BuyMonthlyRate=0,MAX(0,LoanForHome_TargetHomePrice-Installment_TargetHomePrice*120),MAX(0,LoanForHome_TargetHomePrice*(1+BuyMonthlyRate)^(120)-Installment_TargetHomePrice*(((1+BuyMonthlyRate)^(120)-1)/BuyMonthlyRate)))) | D19: =B19-C19 | E19: =Installment_TargetHomePrice*MIN(10*12,BuyLoanTenureYears*12) | F19: =F18+TargetHomePrice*(1+ExpectedAppreciationPct)^9*RentalYieldPct
A21: Loan Balance (col C): exponent is parenthesized — ^(months), not ^months — since Excel's ^ binds tighter than *; ^N*12 would silently compute (base)^N*12 instead of (base)^(N*12), understating growth so badly the balance clamped to ฿0 every year.
A22: Total Rent Paid (col F): cumulative, not EstMonthlyRent*months — rent grows with the property's own appreciation at the same constant RentalYieldPct (year 1 = 12*EstMonthlyRent exactly; each later year adds that year's own higher annual rent).
A23: Affordable Home Value @ Year 10 (= Capital Value, Buy) | B23: =B19 | C23: Also used verbatim as RTO's own Year-10 Capital Value at this same basis (Sheet 8/9) — a home's market value doesn't depend on how it was financed.

Sheet 8a. RTO — Recommended
A1: Rent-to-Own — calculateRentToOwn, basis = MaxHomePrice
A3: Reproduces RTO-Payment.xlsx's formulas verbatim for Years 1-3 (see CalculationAssumptions' rto* fields), then models the actual pathway: at the end of Year 3 the household transitions to a normal mortgage on whatever the RTO contract hasn't already credited toward the price (rows 50-52) — RTO is a 3-year pathway TO ownership, not a flat payment that somehow continues for all 10 years.
A5: RTO Contract Price | B5: =MaxHomePrice*(1+RtoPriceMarkupRate)
A6: Contract Fee (one-time, due at signing) | B6: =MaxHomePrice*RtoContractFeeRate
A7: Monthly RTO Payment | B7: =(RtoPrice_MaxHomePrice/1000000)*RtoPaymentPerMillion | C7: This scenario's "Monthly payment" figure in the comparison grid.
A9: 36-month amortization (imputed interest steps up 1%/yr) — reproduces the sheet's own "After 3 Year" milestone
A10: Month | B10: Imputed Rate (annual) | C10: Interest | D10: Principal | E10: Remaining Balance
A11: 1 | B11: =IF(1<=12,RtoYear1Rate,IF(1<=24,RtoYear2Rate,RtoYear3Rate)) | C11: =RtoPrice_MaxHomePrice*B11/12 | D11: =RtoMonthlyPayment_MaxHomePrice-C11 | E11: =RtoPrice_MaxHomePrice-D11
A12: 2 | B12: =IF(2<=12,RtoYear1Rate,IF(2<=24,RtoYear2Rate,RtoYear3Rate)) | C12: =E11*B12/12 | D12: =RtoMonthlyPayment_MaxHomePrice-C12 | E12: =E11-D12
A13: 3 | B13: =IF(3<=12,RtoYear1Rate,IF(3<=24,RtoYear2Rate,RtoYear3Rate)) | C13: =E12*B13/12 | D13: =RtoMonthlyPayment_MaxHomePrice-C13 | E13: =E12-D13
A14: 4 | B14: =IF(4<=12,RtoYear1Rate,IF(4<=24,RtoYear2Rate,RtoYear3Rate)) | C14: =E13*B14/12 | D14: =RtoMonthlyPayment_MaxHomePrice-C14 | E14: =E13-D14
A15: 5 | B15: =IF(5<=12,RtoYear1Rate,IF(5<=24,RtoYear2Rate,RtoYear3Rate)) | C15: =E14*B15/12 | D15: =RtoMonthlyPayment_MaxHomePrice-C15 | E15: =E14-D15
A16: 6 | B16: =IF(6<=12,RtoYear1Rate,IF(6<=24,RtoYear2Rate,RtoYear3Rate)) | C16: =E15*B16/12 | D16: =RtoMonthlyPayment_MaxHomePrice-C16 | E16: =E15-D16
A17: 7 | B17: =IF(7<=12,RtoYear1Rate,IF(7<=24,RtoYear2Rate,RtoYear3Rate)) | C17: =E16*B17/12 | D17: =RtoMonthlyPayment_MaxHomePrice-C17 | E17: =E16-D17
A18: 8 | B18: =IF(8<=12,RtoYear1Rate,IF(8<=24,RtoYear2Rate,RtoYear3Rate)) | C18: =E17*B18/12 | D18: =RtoMonthlyPayment_MaxHomePrice-C18 | E18: =E17-D18
A19: 9 | B19: =IF(9<=12,RtoYear1Rate,IF(9<=24,RtoYear2Rate,RtoYear3Rate)) | C19: =E18*B19/12 | D19: =RtoMonthlyPayment_MaxHomePrice-C19 | E19: =E18-D19
A20: 10 | B20: =IF(10<=12,RtoYear1Rate,IF(10<=24,RtoYear2Rate,RtoYear3Rate)) | C20: =E19*B20/12 | D20: =RtoMonthlyPayment_MaxHomePrice-C20 | E20: =E19-D20
A21: 11 | B21: =IF(11<=12,RtoYear1Rate,IF(11<=24,RtoYear2Rate,RtoYear3Rate)) | C21: =E20*B21/12 | D21: =RtoMonthlyPayment_MaxHomePrice-C21 | E21: =E20-D21
A22: 12 | B22: =IF(12<=12,RtoYear1Rate,IF(12<=24,RtoYear2Rate,RtoYear3Rate)) | C22: =E21*B22/12 | D22: =RtoMonthlyPayment_MaxHomePrice-C22 | E22: =E21-D22
A23: 13 | B23: =IF(13<=12,RtoYear1Rate,IF(13<=24,RtoYear2Rate,RtoYear3Rate)) | C23: =E22*B23/12 | D23: =RtoMonthlyPayment_MaxHomePrice-C23 | E23: =E22-D23
A24: 14 | B24: =IF(14<=12,RtoYear1Rate,IF(14<=24,RtoYear2Rate,RtoYear3Rate)) | C24: =E23*B24/12 | D24: =RtoMonthlyPayment_MaxHomePrice-C24 | E24: =E23-D24
A25: 15 | B25: =IF(15<=12,RtoYear1Rate,IF(15<=24,RtoYear2Rate,RtoYear3Rate)) | C25: =E24*B25/12 | D25: =RtoMonthlyPayment_MaxHomePrice-C25 | E25: =E24-D25
A26: 16 | B26: =IF(16<=12,RtoYear1Rate,IF(16<=24,RtoYear2Rate,RtoYear3Rate)) | C26: =E25*B26/12 | D26: =RtoMonthlyPayment_MaxHomePrice-C26 | E26: =E25-D26
A27: 17 | B27: =IF(17<=12,RtoYear1Rate,IF(17<=24,RtoYear2Rate,RtoYear3Rate)) | C27: =E26*B27/12 | D27: =RtoMonthlyPayment_MaxHomePrice-C27 | E27: =E26-D27
A28: 18 | B28: =IF(18<=12,RtoYear1Rate,IF(18<=24,RtoYear2Rate,RtoYear3Rate)) | C28: =E27*B28/12 | D28: =RtoMonthlyPayment_MaxHomePrice-C28 | E28: =E27-D28
A29: 19 | B29: =IF(19<=12,RtoYear1Rate,IF(19<=24,RtoYear2Rate,RtoYear3Rate)) | C29: =E28*B29/12 | D29: =RtoMonthlyPayment_MaxHomePrice-C29 | E29: =E28-D29
A30: 20 | B30: =IF(20<=12,RtoYear1Rate,IF(20<=24,RtoYear2Rate,RtoYear3Rate)) | C30: =E29*B30/12 | D30: =RtoMonthlyPayment_MaxHomePrice-C30 | E30: =E29-D30
A31: 21 | B31: =IF(21<=12,RtoYear1Rate,IF(21<=24,RtoYear2Rate,RtoYear3Rate)) | C31: =E30*B31/12 | D31: =RtoMonthlyPayment_MaxHomePrice-C31 | E31: =E30-D31
A32: 22 | B32: =IF(22<=12,RtoYear1Rate,IF(22<=24,RtoYear2Rate,RtoYear3Rate)) | C32: =E31*B32/12 | D32: =RtoMonthlyPayment_MaxHomePrice-C32 | E32: =E31-D32
A33: 23 | B33: =IF(23<=12,RtoYear1Rate,IF(23<=24,RtoYear2Rate,RtoYear3Rate)) | C33: =E32*B33/12 | D33: =RtoMonthlyPayment_MaxHomePrice-C33 | E33: =E32-D33
A34: 24 | B34: =IF(24<=12,RtoYear1Rate,IF(24<=24,RtoYear2Rate,RtoYear3Rate)) | C34: =E33*B34/12 | D34: =RtoMonthlyPayment_MaxHomePrice-C34 | E34: =E33-D34
A35: 25 | B35: =IF(25<=12,RtoYear1Rate,IF(25<=24,RtoYear2Rate,RtoYear3Rate)) | C35: =E34*B35/12 | D35: =RtoMonthlyPayment_MaxHomePrice-C35 | E35: =E34-D35
A36: 26 | B36: =IF(26<=12,RtoYear1Rate,IF(26<=24,RtoYear2Rate,RtoYear3Rate)) | C36: =E35*B36/12 | D36: =RtoMonthlyPayment_MaxHomePrice-C36 | E36: =E35-D36
A37: 27 | B37: =IF(27<=12,RtoYear1Rate,IF(27<=24,RtoYear2Rate,RtoYear3Rate)) | C37: =E36*B37/12 | D37: =RtoMonthlyPayment_MaxHomePrice-C37 | E37: =E36-D37
A38: 28 | B38: =IF(28<=12,RtoYear1Rate,IF(28<=24,RtoYear2Rate,RtoYear3Rate)) | C38: =E37*B38/12 | D38: =RtoMonthlyPayment_MaxHomePrice-C38 | E38: =E37-D38
A39: 29 | B39: =IF(29<=12,RtoYear1Rate,IF(29<=24,RtoYear2Rate,RtoYear3Rate)) | C39: =E38*B39/12 | D39: =RtoMonthlyPayment_MaxHomePrice-C39 | E39: =E38-D39
A40: 30 | B40: =IF(30<=12,RtoYear1Rate,IF(30<=24,RtoYear2Rate,RtoYear3Rate)) | C40: =E39*B40/12 | D40: =RtoMonthlyPayment_MaxHomePrice-C40 | E40: =E39-D40
A41: 31 | B41: =IF(31<=12,RtoYear1Rate,IF(31<=24,RtoYear2Rate,RtoYear3Rate)) | C41: =E40*B41/12 | D41: =RtoMonthlyPayment_MaxHomePrice-C41 | E41: =E40-D41
A42: 32 | B42: =IF(32<=12,RtoYear1Rate,IF(32<=24,RtoYear2Rate,RtoYear3Rate)) | C42: =E41*B42/12 | D42: =RtoMonthlyPayment_MaxHomePrice-C42 | E42: =E41-D42
A43: 33 | B43: =IF(33<=12,RtoYear1Rate,IF(33<=24,RtoYear2Rate,RtoYear3Rate)) | C43: =E42*B43/12 | D43: =RtoMonthlyPayment_MaxHomePrice-C43 | E43: =E42-D43
...

Sheet 8b. RTO — Target Price
A1: Rent-to-Own — calculateRentToOwn, basis = TargetHomePrice
A3: Reproduces RTO-Payment.xlsx's formulas verbatim for Years 1-3 (see CalculationAssumptions' rto* fields), then models the actual pathway: at the end of Year 3 the household transitions to a normal mortgage on whatever the RTO contract hasn't already credited toward the price (rows 50-52) — RTO is a 3-year pathway TO ownership, not a flat payment that somehow continues for all 10 years.
A5: RTO Contract Price | B5: =TargetHomePrice*(1+RtoPriceMarkupRate)
A6: Contract Fee (one-time, due at signing) | B6: =TargetHomePrice*RtoContractFeeRate
A7: Monthly RTO Payment | B7: =(RtoPrice_TargetHomePrice/1000000)*RtoPaymentPerMillion | C7: This scenario's "Monthly payment" figure in the comparison grid.
A9: 36-month amortization (imputed interest steps up 1%/yr) — reproduces the sheet's own "After 3 Year" milestone
A10: Month | B10: Imputed Rate (annual) | C10: Interest | D10: Principal | E10: Remaining Balance
A11: 1 | B11: =IF(1<=12,RtoYear1Rate,IF(1<=24,RtoYear2Rate,RtoYear3Rate)) | C11: =RtoPrice_TargetHomePrice*B11/12 | D11: =RtoMonthlyPayment_TargetHomePrice-C11 | E11: =RtoPrice_TargetHomePrice-D11
A12: 2 | B12: =IF(2<=12,RtoYear1Rate,IF(2<=24,RtoYear2Rate,RtoYear3Rate)) | C12: =E11*B12/12 | D12: =RtoMonthlyPayment_TargetHomePrice-C12 | E12: =E11-D12
A13: 3 | B13: =IF(3<=12,RtoYear1Rate,IF(3<=24,RtoYear2Rate,RtoYear3Rate)) | C13: =E12*B13/12 | D13: =RtoMonthlyPayment_TargetHomePrice-C13 | E13: =E12-D13
A14: 4 | B14: =IF(4<=12,RtoYear1Rate,IF(4<=24,RtoYear2Rate,RtoYear3Rate)) | C14: =E13*B14/12 | D14: =RtoMonthlyPayment_TargetHomePrice-C14 | E14: =E13-D14
A15: 5 | B15: =IF(5<=12,RtoYear1Rate,IF(5<=24,RtoYear2Rate,RtoYear3Rate)) | C15: =E14*B15/12 | D15: =RtoMonthlyPayment_TargetHomePrice-C15 | E15: =E14-D15
A16: 6 | B16: =IF(6<=12,RtoYear1Rate,IF(6<=24,RtoYear2Rate,RtoYear3Rate)) | C16: =E15*B16/12 | D16: =RtoMonthlyPayment_TargetHomePrice-C16 | E16: =E15-D16
A17: 7 | B17: =IF(7<=12,RtoYear1Rate,IF(7<=24,RtoYear2Rate,RtoYear3Rate)) | C17: =E16*B17/12 | D17: =RtoMonthlyPayment_TargetHomePrice-C17 | E17: =E16-D17
A18: 8 | B18: =IF(8<=12,RtoYear1Rate,IF(8<=24,RtoYear2Rate,RtoYear3Rate)) | C18: =E17*B18/12 | D18: =RtoMonthlyPayment_TargetHomePrice-C18 | E18: =E17-D18
A19: 9 | B19: =IF(9<=12,RtoYear1Rate,IF(9<=24,RtoYear2Rate,RtoYear3Rate)) | C19: =E18*B19/12 | D19: =RtoMonthlyPayment_TargetHomePrice-C19 | E19: =E18-D19
A20: 10 | B20: =IF(10<=12,RtoYear1Rate,IF(10<=24,RtoYear2Rate,RtoYear3Rate)) | C20: =E19*B20/12 | D20: =RtoMonthlyPayment_TargetHomePrice-C20 | E20: =E19-D20
A21: 11 | B21: =IF(11<=12,RtoYear1Rate,IF(11<=24,RtoYear2Rate,RtoYear3Rate)) | C21: =E20*B21/12 | D21: =RtoMonthlyPayment_TargetHomePrice-C21 | E21: =E20-D21
A22: 12 | B22: =IF(12<=12,RtoYear1Rate,IF(12<=24,RtoYear2Rate,RtoYear3Rate)) | C22: =E21*B22/12 | D22: =RtoMonthlyPayment_TargetHomePrice-C22 | E22: =E21-D22
A23: 13 | B23: =IF(13<=12,RtoYear1Rate,IF(13<=24,RtoYear2Rate,RtoYear3Rate)) | C23: =E22*B23/12 | D23: =RtoMonthlyPayment_TargetHomePrice-C23 | E23: =E22-D23
A24: 14 | B24: =IF(14<=12,RtoYear1Rate,IF(14<=24,RtoYear2Rate,RtoYear3Rate)) | C24: =E23*B24/12 | D24: =RtoMonthlyPayment_TargetHomePrice-C24 | E24: =E23-D24
A25: 15 | B25: =IF(15<=12,RtoYear1Rate,IF(15<=24,RtoYear2Rate,RtoYear3Rate)) | C25: =E24*B25/12 | D25: =RtoMonthlyPayment_TargetHomePrice-C25 | E25: =E24-D25
A26: 16 | B26: =IF(16<=12,RtoYear1Rate,IF(16<=24,RtoYear2Rate,RtoYear3Rate)) | C26: =E25*B26/12 | D26: =RtoMonthlyPayment_TargetHomePrice-C26 | E26: =E25-D26
A27: 17 | B27: =IF(17<=12,RtoYear1Rate,IF(17<=24,RtoYear2Rate,RtoYear3Rate)) | C27: =E26*B27/12 | D27: =RtoMonthlyPayment_TargetHomePrice-C27 | E27: =E26-D27
A28: 18 | B28: =IF(18<=12,RtoYear1Rate,IF(18<=24,RtoYear2Rate,RtoYear3Rate)) | C28: =E27*B28/12 | D28: =RtoMonthlyPayment_TargetHomePrice-C28 | E28: =E27-D28
A29: 19 | B29: =IF(19<=12,RtoYear1Rate,IF(19<=24,RtoYear2Rate,RtoYear3Rate)) | C29: =E28*B29/12 | D29: =RtoMonthlyPayment_TargetHomePrice-C29 | E29: =E28-D29
A30: 20 | B30: =IF(20<=12,RtoYear1Rate,IF(20<=24,RtoYear2Rate,RtoYear3Rate)) | C30: =E29*B30/12 | D30: =RtoMonthlyPayment_TargetHomePrice-C30 | E30: =E29-D30
A31: 21 | B31: =IF(21<=12,RtoYear1Rate,IF(21<=24,RtoYear2Rate,RtoYear3Rate)) | C31: =E30*B31/12 | D31: =RtoMonthlyPayment_TargetHomePrice-C31 | E31: =E30-D31
A32: 22 | B32: =IF(22<=12,RtoYear1Rate,IF(22<=24,RtoYear2Rate,RtoYear3Rate)) | C32: =E31*B32/12 | D32: =RtoMonthlyPayment_TargetHomePrice-C32 | E32: =E31-D32
A33: 23 | B33: =IF(23<=12,RtoYear1Rate,IF(23<=24,RtoYear2Rate,RtoYear3Rate)) | C33: =E32*B33/12 | D33: =RtoMonthlyPayment_TargetHomePrice-C33 | E33: =E32-D33
A34: 24 | B34: =IF(24<=12,RtoYear1Rate,IF(24<=24,RtoYear2Rate,RtoYear3Rate)) | C34: =E33*B34/12 | D34: =RtoMonthlyPayment_TargetHomePrice-C34 | E34: =E33-D34
A35: 25 | B35: =IF(25<=12,RtoYear1Rate,IF(25<=24,RtoYear2Rate,RtoYear3Rate)) | C35: =E34*B35/12 | D35: =RtoMonthlyPayment_TargetHomePrice-C35 | E35: =E34-D35
A36: 26 | B36: =IF(26<=12,RtoYear1Rate,IF(26<=24,RtoYear2Rate,RtoYear3Rate)) | C36: =E35*B36/12 | D36: =RtoMonthlyPayment_TargetHomePrice-C36 | E36: =E35-D36
A37: 27 | B37: =IF(27<=12,RtoYear1Rate,IF(27<=24,RtoYear2Rate,RtoYear3Rate)) | C37: =E36*B37/12 | D37: =RtoMonthlyPayment_TargetHomePrice-C37 | E37: =E36-D37
A38: 28 | B38: =IF(28<=12,RtoYear1Rate,IF(28<=24,RtoYear2Rate,RtoYear3Rate)) | C38: =E37*B38/12 | D38: =RtoMonthlyPayment_TargetHomePrice-C38 | E38: =E37-D38
A39: 29 | B39: =IF(29<=12,RtoYear1Rate,IF(29<=24,RtoYear2Rate,RtoYear3Rate)) | C39: =E38*B39/12 | D39: =RtoMonthlyPayment_TargetHomePrice-C39 | E39: =E38-D39
A40: 30 | B40: =IF(30<=12,RtoYear1Rate,IF(30<=24,RtoYear2Rate,RtoYear3Rate)) | C40: =E39*B40/12 | D40: =RtoMonthlyPayment_TargetHomePrice-C40 | E40: =E39-D40
A41: 31 | B41: =IF(31<=12,RtoYear1Rate,IF(31<=24,RtoYear2Rate,RtoYear3Rate)) | C41: =E40*B41/12 | D41: =RtoMonthlyPayment_TargetHomePrice-C41 | E41: =E40-D41
A42: 32 | B42: =IF(32<=12,RtoYear1Rate,IF(32<=24,RtoYear2Rate,RtoYear3Rate)) | C42: =E41*B42/12 | D42: =RtoMonthlyPayment_TargetHomePrice-C42 | E42: =E41-D42
A43: 33 | B43: =IF(33<=12,RtoYear1Rate,IF(33<=24,RtoYear2Rate,RtoYear3Rate)) | C43: =E42*B43/12 | D43: =RtoMonthlyPayment_TargetHomePrice-C43 | E43: =E42-D43
...

Sheet 9a. Cash Flow — Recommended
A1: Cash Flow Comparison — calculateBuyVsRentCashFlow, basis = MaxHomePrice
A3: "Remaining Monthly Income" = Income After Other Obligations (Sheet 3) minus THIS option's own monthly housing payment — bonus excluded, debt/living-expenses/lump-sum already excluded upstream in Sheet 3. Row 11 (Total Paid Over 10 Years): Rent reads Sheet 7's own growing cumulative total (not a flat multiply — rent grows with property appreciation); RTO reads Sheet 8's Total Paid Over 10 Years (RTO), which itself splits into 3 years of RTO payments + 7 years of a post-transition mortgage — never a flat monthly payment for all 10 years. Buy alone stays a flat multiply (a mortgage installment genuinely is fixed for its whole term). Row 13 (Net Cash Flow over 10 Years) is Capital Value minus Total Paid (calculateNetCashFlow10Years) — Rent's Capital Value counts as ฿0 since it never accumulates, so Rent's Net Cash Flow is simply its Total Paid, negated.
B5: Rent | C5: Rent-to-Own | D5: Buy
A6: Monthly Housing Payment | B6: =EstMonthlyRent_MaxHomePrice | C6: =RtoMonthlyPayment_MaxHomePrice | D6: =Installment_MaxHomePrice
A7: Remaining Monthly Income | B7: =IncomeAfterOtherObligations-B6 | C7: =IncomeAfterOtherObligations-C6 | D7: =IncomeAfterOtherObligations-D6
A8: Remaining % of Steady Income | B8: =IF(SteadyMonthlyIncome>0,B7/SteadyMonthlyIncome*100,0) | C8: =IF(SteadyMonthlyIncome>0,C7/SteadyMonthlyIncome*100,0) | D8: =IF(SteadyMonthlyIncome>0,D7/SteadyMonthlyIncome*100,0)
A9: Cushion Status | B9: =IF(B8>=ComfortableThreshold*100,"Comfortable",IF(B8>=TightThreshold*100,"Tight","High Risk")) | C9: =IF(C8>=ComfortableThreshold*100,"Comfortable",IF(C8>=TightThreshold*100,"Tight","High Risk")) | D9: =IF(D8>=ComfortableThreshold*100,"Comfortable",IF(D8>=TightThreshold*100,"Tight","High Risk"))
A10: Initial Payment (one-time) | B10: =EstMonthlyRent_MaxHomePrice*2 | C10: =RtoContractFee_MaxHomePrice | D10: =MaxHomePrice*DownPaymentRate+MaxHomePrice*TransactionCostRate
A11: Total Paid Over 10 Years | B11: ='7a. Wealth — Recommended'!F19 | C11: =RtoTotalPaid10Y_MaxHomePrice | D11: =D6*120+D10
A12: Capital Value @ Year 10 | B12: No capital value (renting) | C12: =RtoHomeValueYear10_MaxHomePrice | D12: =HomeValueYear10_MaxHomePrice
A13: Net Cash Flow over 10 Years | B13: =0-B11 | C13: =C12-C11 | D13: =D12-D11
A15: Row references used elsewhere: Remaining Monthly Income row = 7, Cushion Status row = 9, Remaining % row = 8, Net Cash Flow row = 13.

Sheet 9b. Cash Flow — Target Price
A1: Cash Flow Comparison — calculateBuyVsRentCashFlow, basis = TargetHomePrice
A3: "Remaining Monthly Income" = Income After Other Obligations (Sheet 3) minus THIS option's own monthly housing payment — bonus excluded, debt/living-expenses/lump-sum already excluded upstream in Sheet 3. Row 11 (Total Paid Over 10 Years): Rent reads Sheet 7's own growing cumulative total (not a flat multiply — rent grows with property appreciation); RTO reads Sheet 8's Total Paid Over 10 Years (RTO), which itself splits into 3 years of RTO payments + 7 years of a post-transition mortgage — never a flat monthly payment for all 10 years. Buy alone stays a flat multiply (a mortgage installment genuinely is fixed for its whole term). Row 13 (Net Cash Flow over 10 Years) is Capital Value minus Total Paid (calculateNetCashFlow10Years) — Rent's Capital Value counts as ฿0 since it never accumulates, so Rent's Net Cash Flow is simply its Total Paid, negated.
B5: Rent | C5: Rent-to-Own | D5: Buy
A6: Monthly Housing Payment | B6: =EstMonthlyRent_TargetHomePrice | C6: =RtoMonthlyPayment_TargetHomePrice | D6: =Installment_TargetHomePrice
A7: Remaining Monthly Income | B7: =IncomeAfterOtherObligations-B6 | C7: =IncomeAfterOtherObligations-C6 | D7: =IncomeAfterOtherObligations-D6
A8: Remaining % of Steady Income | B8: =IF(SteadyMonthlyIncome>0,B7/SteadyMonthlyIncome*100,0) | C8: =IF(SteadyMonthlyIncome>0,C7/SteadyMonthlyIncome*100,0) | D8: =IF(SteadyMonthlyIncome>0,D7/SteadyMonthlyIncome*100,0)
A9: Cushion Status | B9: =IF(B8>=ComfortableThreshold*100,"Comfortable",IF(B8>=TightThreshold*100,"Tight","High Risk")) | C9: =IF(C8>=ComfortableThreshold*100,"Comfortable",IF(C8>=TightThreshold*100,"Tight","High Risk")) | D9: =IF(D8>=ComfortableThreshold*100,"Comfortable",IF(D8>=TightThreshold*100,"Tight","High Risk"))
A10: Initial Payment (one-time) | B10: =EstMonthlyRent_TargetHomePrice*2 | C10: =RtoContractFee_TargetHomePrice | D10: =TargetHomePrice*DownPaymentRate+TargetHomePrice*TransactionCostRate
A11: Total Paid Over 10 Years | B11: ='7b. Wealth — Target Price'!F19 | C11: =RtoTotalPaid10Y_TargetHomePrice | D11: =D6*120+D10
A12: Capital Value @ Year 10 | B12: No capital value (renting) | C12: =RtoHomeValueYear10_TargetHomePrice | D12: =HomeValueYear10_TargetHomePrice
A13: Net Cash Flow over 10 Years | B13: =0-B11 | C13: =C12-C11 | D13: =D12-D11
A15: Row references used elsewhere: Remaining Monthly Income row = 7, Cushion Status row = 9, Remaining % row = 8, Net Cash Flow row = 13.

Sheet 10a. RTO Plan — Recommended
A1: Gap & Plan — Rent-to-Own, basis = Recommended Home Price
A3: RTO no longer computes its own 'affordable home price' — Buy and RTO share ONE financial-eligibility ceiling (Home Price Gap below, informational only: there is no RTO-specific lever that closes it, since closing it means more loan capacity — Buy's own action, see 4a. Home Price Gap (Rec)). This sheet's PLAN is entirely RTO-specific cash-flow math: the contract fee (an upfront cash requirement Buy doesn't have) and the actual RTO monthly payment's own feasibility during Years 1-3 (never Buy's installment math).
A5: THE GAP
A6: Home Price Gap (shared eligibility check with Buy — see 4a. Home Price Gap (Rec)) | B6: ='4a. Home Price Gap (Rec)'!B7
A7: Contract Fee (required upfront) | B7: =RtoContractFee_MaxHomePrice
A8: Available Down Payment | B8: =AvailableDownPayment
A9: Contract Fee Gap | B9: =MAX(0,RtoContractFee_MaxHomePrice-AvailableDownPayment)
A10: Is Contract Fee Gap Closed | B10: =RtoContractFeeGap_MaxHomePrice=0
A11: Monthly Shortfall (during the 3-year RTO period) | B11: =IF(RtoHasShortfall_MaxHomePrice,ABS(RtoRemainingMonthly_MaxHomePrice),0) | C11: How much more the household would need each month to afford the actual RTO payment during Years 1-3 — computed from RTO's own monthly payment (row 19 below), never Buy's installment math. ฿0 when there's no shortfall.
A12: In the app: a GAP row is hidden whenever its amount is ฿0 (all three rows above).
A13: THE PLAN
A14: 1. Complete your contract fee
A15: Months to Close Contract Fee Gap | B15: =IF(RtoContractFeeGapClosed_MaxHomePrice,0,IF(MonthlySavingCapacity>0,CEILING(RtoContractFeeGap_MaxHomePrice/MonthlySavingCapacity,1),"N/A (saving $0/mo)"))
A18: 2. Close the monthly shortfall — Years 1-3 (if any)
A19: RTO Monthly Payment (Years 1-3) | B19: =RtoMonthlyPayment_MaxHomePrice
A20: Remaining Monthly Income (from 9a. Cash Flow — Recommended) | B20: ='9a. Cash Flow — Recommended'!C7
A21: Cushion Status (from 9a. Cash Flow — Recommended) | B21: ='9a. Cash Flow — Recommended'!C9
A22: Has Monthly Shortfall | B22: =B20<0
A23: Monthly Shortfall (if any) — same figure as THE GAP row above | B23: =B11
A27: ADDITIONAL OPTION
A28: IDENTICAL to Buy's — same stretch/risk-zone tiers, same copy (see 4a. Home Price Gap (Rec) rows below). No separate RTO-only 'lower to Recommended Price' message anymore.
A29: Downsize Suggestion (shared — see 4a. Home Price Gap (Rec)) | B29: ='4a. Home Price Gap (Rec)'!B18
A30: Amount over Stretch Budget (if over-risk-budget) | B30: ='4a. Home Price Gap (Rec)'!B19

Sheet 10b. RTO Plan — Target Price
A1: Gap & Plan — Rent-to-Own, basis = Target Home Price
A3: RTO no longer computes its own 'affordable home price' — Buy and RTO share ONE financial-eligibility ceiling (Home Price Gap below, informational only: there is no RTO-specific lever that closes it, since closing it means more loan capacity — Buy's own action, see 4b. Home Price Gap (Tgt)). This sheet's PLAN is entirely RTO-specific cash-flow math: the contract fee (an upfront cash requirement Buy doesn't have) and the actual RTO monthly payment's own feasibility during Years 1-3 (never Buy's installment math).
A5: THE GAP
A6: Home Price Gap (shared eligibility check with Buy — see 4b. Home Price Gap (Tgt)) | B6: ='4b. Home Price Gap (Tgt)'!B7
A7: Contract Fee (required upfront) | B7: =RtoContractFee_TargetHomePrice
A8: Available Down Payment | B8: =AvailableDownPayment
A9: Contract Fee Gap | B9: =MAX(0,RtoContractFee_TargetHomePrice-AvailableDownPayment)
A10: Is Contract Fee Gap Closed | B10: =RtoContractFeeGap_TargetHomePrice=0
A11: Monthly Shortfall (during the 3-year RTO period) | B11: =IF(RtoHasShortfall_TargetHomePrice,ABS(RtoRemainingMonthly_TargetHomePrice),0) | C11: How much more the household would need each month to afford the actual RTO payment during Years 1-3 — computed from RTO's own monthly payment (row 19 below), never Buy's installment math. ฿0 when there's no shortfall.
A12: In the app: a GAP row is hidden whenever its amount is ฿0 (all three rows above).
A13: THE PLAN
A14: 1. Complete your contract fee
A15: Months to Close Contract Fee Gap | B15: =IF(RtoContractFeeGapClosed_TargetHomePrice,0,IF(MonthlySavingCapacity>0,CEILING(RtoContractFeeGap_TargetHomePrice/MonthlySavingCapacity,1),"N/A (saving $0/mo)"))
A18: 2. Close the monthly shortfall — Years 1-3 (if any)
A19: RTO Monthly Payment (Years 1-3) | B19: =RtoMonthlyPayment_TargetHomePrice
A20: Remaining Monthly Income (from 9b. Cash Flow — Target Price) | B20: ='9b. Cash Flow — Target Price'!C7
A21: Cushion Status (from 9b. Cash Flow — Target Price) | B21: ='9b. Cash Flow — Target Price'!C9
A22: Has Monthly Shortfall | B22: =B20<0
A23: Monthly Shortfall (if any) — same figure as THE GAP row above | B23: =B11
A27: ADDITIONAL OPTION
A28: IDENTICAL to Buy's — same stretch/risk-zone tiers, same copy (see 4b. Home Price Gap (Tgt) rows below). No separate RTO-only 'lower to Recommended Price' message anymore.
A29: Downsize Suggestion (shared — see 4b. Home Price Gap (Tgt)) | B29: ='4b. Home Price Gap (Tgt)'!B18
A30: Amount over Stretch Budget (if over-risk-budget) | B30: ='4b. Home Price Gap (Tgt)'!B19

Sheet 11a. Rent Plan — Recommended
A1: Gap & Plan — Rent, basis = Recommended Home Price
A3: Renting DOES have a real upfront cash requirement — the 2-month rental deposit, checked against Total Savings (not Available Down Payment — Rent needs no down payment at all).
A5: THE GAP
A6: Required Rental Deposit (2 months' rent) | B6: ='9a. Cash Flow — Recommended'!B10 | C6: =CashFlowBreakdown.initialPaymentTHB for Rent, reused verbatim.
A7: Total Savings Available | B7: =TotalSavings
A8: Rental Deposit Gap | B8: =MAX(0,RentRequiredDeposit_MaxHomePrice-TotalSavings)
A9: Is Rental Deposit Ready | B9: =RentDepositGap_MaxHomePrice=0
A10: Remaining Monthly Income (from 9a. Cash Flow — Recommended) | B10: ='9a. Cash Flow — Recommended'!B7
A11: Has Monthly Shortfall | B11: =RentRemainingMonthly_MaxHomePrice<0
A12: Monthly Shortfall (if any) | B12: =IF(RentHasShortfall_MaxHomePrice,ABS(RentRemainingMonthly_MaxHomePrice),0)
A13: In the app: Rental Deposit Gap row is hidden when ฿0; Monthly Shortfall row is hidden unless there IS a shortfall.
A15: THE PLAN
A16: Months to Close Rental Deposit Gap | B16: =IF(RentDepositReady_MaxHomePrice,0,IF(MonthlySavingCapacity>0,CEILING(RentDepositGap_MaxHomePrice/MonthlySavingCapacity,1),"N/A (saving $0/mo)"))
A17: Close the monthly shortfall (action) | B17: ="Consider a lower rent budget, higher income, or lower existing debt"

Sheet 11b. Rent Plan — Target Price
A1: Gap & Plan — Rent, basis = Target Home Price
A3: Renting DOES have a real upfront cash requirement — the 2-month rental deposit, checked against Total Savings (not Available Down Payment — Rent needs no down payment at all).
A5: THE GAP
A6: Required Rental Deposit (2 months' rent) | B6: ='9b. Cash Flow — Target Price'!B10 | C6: =CashFlowBreakdown.initialPaymentTHB for Rent, reused verbatim.
A7: Total Savings Available | B7: =TotalSavings
A8: Rental Deposit Gap | B8: =MAX(0,RentRequiredDeposit_TargetHomePrice-TotalSavings)
A9: Is Rental Deposit Ready | B9: =RentDepositGap_TargetHomePrice=0
A10: Remaining Monthly Income (from 9b. Cash Flow — Target Price) | B10: ='9b. Cash Flow — Target Price'!B7
A11: Has Monthly Shortfall | B11: =RentRemainingMonthly_TargetHomePrice<0
A12: Monthly Shortfall (if any) | B12: =IF(RentHasShortfall_TargetHomePrice,ABS(RentRemainingMonthly_TargetHomePrice),0)
A13: In the app: Rental Deposit Gap row is hidden when ฿0; Monthly Shortfall row is hidden unless there IS a shortfall.
A15: THE PLAN
A16: Months to Close Rental Deposit Gap | B16: =IF(RentDepositReady_TargetHomePrice,0,IF(MonthlySavingCapacity>0,CEILING(RentDepositGap_TargetHomePrice/MonthlySavingCapacity,1),"N/A (saving $0/mo)"))
A17: Close the monthly shortfall (action) | B17: ="Consider a lower rent budget, higher income, or lower existing debt"

Sheet 12. Advisory Notices
A1: Advisory Notices — getAdvisoryNotices
A3: Warning-only: reads ONLY Monthly Cash Flow Before Housing (Sheet 3) — structurally can never affect any affordability number or the Readiness Score.
A5: Negative Cash Flow Before Housing? | B5: =MonthlyCashFlowBeforeHousing<0
A6: Amount (if negative) | B6: =IF(MonthlyCashFlowBeforeHousing<0,ABS(MonthlyCashFlowBeforeHousing),"-")
